Workbook

Sheet Start
B2: KI wirtschaftlich einsetzen
B3: Rechenmodell zum Buch von Maximilian Rosen · Version 1.0 · Preisstand 23.10.2026 · alle Beträge netto
B5: In drei Schritten zur eigenen Rechnung
B6: 1. Öffnen Sie das Blatt „Mein Vorhaben“ (Link unten).
B7: 2. Ersetzen Sie die blau hinterlegten Beispielwerte durch Ihre eigenen Zahlen. Graue Felder rechnet die Tabelle selbst.
B8: 3. Lesen Sie Zeile „Einschätzung“ und die Hinweise. Rote Hinweise bedeuten: Eingaben prüfen.
B10: =HYPERLINK("#'Mein Vorhaben'!A1","→ Zum Blatt „Mein Vorhaben“") -> → Zum Blatt „Mein Vorhaben“
B12: Was Sie dafür brauchen
B13: Anzahl der Vorgänge je Monat, gemessene Minuten je Vorgang heute, Arbeitskosten je Stunde (Lohnbuchhaltung), Angebot des Dienstleisters mit einmaligen und laufenden Kosten.
B15: Farben
B16: Blau hinterlegt = Eingabe · Grau = Ergebnis · Grün = wichtigstes Ergebnis · Gelb (Buchblätter) = einflussreiche Annahme
B17: Formeln sind gegen versehentliches Überschreiben geschützt. Schutz aufheben: Überprüfen › Blattschutz aufheben (kein Kennwort).
B19: Weitere Blätter
B20: Die übrigen Blätter enthalten alle Rechnungen des Buches (Kapitel 3 bis 11). Eine Übersicht steht im Blatt „Anleitung“.
B22: Wichtig
B23: Frei werdende Arbeitszeit ist nicht automatisch eingespartes Geld. Die Tabelle weist beides getrennt aus.
B24: Die Ergebnisse sind Modellrechnungen mit Ihren Annahmen. Messen Sie die Werte vor einer Entscheidung im Pilotprojekt (Kapitel 11). Keine Makros, keine Datenverbindungen.

Sheet Mein Vorhaben
A1: Mein Vorhaben: Rechnet sich die KI-Anwendung?
A2: Blau hinterlegte Felder sind Eingaben: tragen Sie Ihre eigenen Werte ein. Grau hinterlegte Felder rechnet die Tabelle selbst. Alle Beträge netto. Vorbelegt ist das Beispiel aus Kapitel 5 des Buches (mittleres Volumen); „Vorsichtig“ halbiert die Zeitersparnis wie die Empfindlichkeitsrechnung im Buch.
A3: Rechenweg und Begriffe: Kapitel 5 und Anhang A des Buches. Ergebnisse sind Modellrechnungen, keine Zusage.
A5: Eingabe | B5: Vorsichtig | C5: Erwartet | D5: Ihre Variante | E5: Einheit | F5: Erläuterung
A6: Vorgänge je Monat | B6: 600 | C6: 600 | D6: 600 | E6: Anzahl | F6: Wie oft fällt der Vorgang im Monat an? Am besten zählen statt schätzen.
A7: Minuten je Vorgang heute (ohne KI) | B7: 6 | C7: 6 | D7: 6 | E7: min | F7: Gemessene Bearbeitungszeit heute, gemittelt über einfache und schwierige Fälle.
A8: Minuten je Vorgang mit KI (Prüfen und Freigeben) | B8: 4 | C8: 2 | D8: 2 | E8: min | F8: Zeit, die ein Mensch mit KI noch braucht. Vorsichtig: halbe Zeitersparnis.
A9: Anteil der Vorgänge mit Nacharbeit | B9: 0.08 | C9: 0.08 | D9: 0.08 | E9: % | F9: Wie oft muss das KI-Ergebnis korrigiert werden? Im Pilotprojekt messen.
A10: Minuten je Nacharbeit | B10: 5 | C10: 5 | D10: 5 | E10: min | F10: Zusätzliche Zeit, wenn korrigiert werden muss.
A11: Arbeitskosten je geleistete Stunde | B11: 45 | C11: 45 | D11: 45 | E11: €/h | F11: Bruttolohn plus Arbeitgeberanteile, geteilt durch tatsächlich geleistete Stunden (Blatt Arbeitskosten).
A12: KI-Kosten je Vorgang | B12: =Wirtschaftlichkeit!$C$10 -> 0.0095652174 | C12: =Wirtschaftlichkeit!$C$10 -> 0.0095652174 | D12: =Wirtschaftlichkeit!$C$10 -> 0.0095652174 | E12: € | F12: Vorbelegt aus dem Buchbeispiel (rund 1 Cent). Für eigene Werte: Blatt Vorgangsrechner oder Angebot des Dienstleisters.
A13: Feste Software- und Plattformkosten | B13: 50 | C13: 50 | D13: 50 | E13: €/Monat | F13: Monatliche Gebühren, z. B. für einen Automatisierungsdienst.
A14: Wartung und Kontrolle | B14: 4 | C14: 4 | D14: 4 | E14: h/Monat | F14: Stichproben, Anpassungen, Störungen.
A15: Neutest nach Modell- oder Anbieterwechsel | B15: 8 | C15: 8 | D15: 8 | E15: h/Jahr | F15: KI-Modelle werden regelmäßig ersetzt; danach muss neu getestet werden.
A16: Einrichtung durch Dienstleister | B16: 50 | C16: 50 | D16: 50 | E16: h | F16: Stunden laut Angebot. Richtet ein eigener Mitarbeiter ein: 0 und die Stunden unten bei den internen Stunden eintragen.
A17: Stundensatz Dienstleister | B17: 100 | C17: 100 | D17: 100 | E17: €/h | F17: Netto-Stundensatz laut Angebot.
A18: Datenschutz und Recht, einmalig | B18: 600 | C18: 600 | D18: 600 | E18: € | F18: Prüfung Auftragsverarbeitung, Verzeichnis, Information, gegebenenfalls Betriebsrat.
A19: IT-Sicherheit, einmalig | B19: 400 | C19: 400 | D19: 400 | E19: € | F19: Zugänge, Rechte, Protokollierung.
A20: Schulung | B20: 12 | C20: 12 | D20: 12 | E20: h gesamt | F20: Summe der Schulungsstunden aller Beteiligten.
A21: Interne Stunden für Auswahl, Testfälle und Pilotprojekt | B21: 16 | C21: 16 | D21: 16 | E21: h gesamt | F21: Bei eigener Einrichtung zusätzlich deren Stunden.
A22: Anteil der frei werdenden Zeit, der tatsächlich Ausgaben vermeidet | B22: 0.3 | C22: 0.3 | D22: 0.3 | E22: % | F22: Nur wenn Überstunden, Aushilfen oder Neueinstellungen wegfallen, spart frei werdende Zeit Geld. 0 % = reiner Kapazitätsgewinn.
A23: Zusätzlicher Deckungsbeitrag je Monat (optional) | B23: 0 | C23: 0 | D23: 0 | E23: €/Monat | F23: Nur Deckungsbeitrag, nicht Umsatz: z. B. bisher vergessene Leistungen, die bezahlt werden, abzüglich Material. Im Zweifel 0.
A24: Betrachtungszeitraum | B24: 24 | C24: 24 | D24: 24 | E24: Monate | F24: KI-Modelle und Preise ändern sich schnell; mehr als 36 Monate sind unsicher.
A26: Ergebnis
A27: Arbeitszeit heute | B27: =B6*B7/60 -> 60 | C27: =C6*C7/60 -> 60 | D27: =D6*D7/60 -> 60 | E27: h/Monat | F27: Vorgänge × Minuten heute.
A28: Arbeitszeit mit KI inkl. Nacharbeit und Wartung | B28: =(B6*B8+B6*B9*B10)/60+B14+B15/12 -> 48.666667 | C28: =(C6*C8+C6*C9*C10)/60+C14+C15/12 -> 28.666667 | D28: =(D6*D8+D6*D9*D10)/60+D14+D15/12 -> 28.666667 | E28: h/Monat | F28: Prüfen, Nacharbeit, Wartung und anteiliger Neutest.
A29: Frei werdende Arbeitszeit (Kapazitätsgewinn) | B29: =B27-B28 -> 11.333333 | C29: =C27-C28 -> 31.333333 | D29: =D27-D28 -> 31.333333 | E29: h/Monat | F29: Zeit, die für andere Aufgaben frei wird. Das ist noch kein Geld.
A30: Kapazitätsgewinn, mit Arbeitskosten bewertet | B30: =B29*B11 -> 510 | C30: =C29*C11 -> 1410 | D30: =D29*D11 -> 1410 | E30: €/Monat | F30: Kalkulatorischer Wert der frei werdenden Zeit.
A31: Laufende Kosten (KI und Software) | B31: =B6*B12+B13 -> 55.73913 | C31: =C6*C12+C13 -> 55.73913 | D31: =D6*D12+D13 -> 55.73913 | E31: €/Monat | F31: Zahlungswirksame Kosten je Monat.
A32: Nettoeffekt kalkulatorisch je Monat | B32: =B30-B31 -> 454.26087 | C32: =C30-C31 -> 1354.2609 | D32: =D30-D31 -> 1354.2609 | E32: €/Monat | F32: Bewertete Zeitersparnis minus laufende Kosten.
A33: Davon tatsächlich vermiedene Auszahlungen | B33: =B30*B22 -> 153 | C33: =C30*C22 -> 423 | D33: =D30*D22 -> 423 | E33: €/Monat | F33: Nur der Anteil aus Zeile 22.
A34: Nettoeffekt zahlungswirksam je Monat | B34: =B33+B23-B31 -> 97.26087 | C34: =C33+C23-C31 -> 367.26087 | D34: =D33+D23-D31 -> 367.26087 | E34: €/Monat | F34: Was am Monatsende tatsächlich auf dem Konto bleibt (inkl. Deckungsbeitrag aus Zeile 23).
A35: Einmalkosten mit Auszahlung | B35: =B16*B17+B18+B19 -> 6000 | C35: =C16*C17+C18+C19 -> 6000 | D35: =D16*D17+D18+D19 -> 6000 | E35: € | F35: Dienstleister, Datenschutz, IT-Sicherheit.
A36: Einmalkosten interne Stunden (bewertet) | B36: =(B20+B21)*B11 -> 1260 | C36: =(C20+C21)*C11 -> 1260 | D36: =(D20+D21)*D11 -> 1260 | E36: € | F36: Schulung und interne Stunden, mit Arbeitskosten bewertet.
A37: Einmalkosten gesamt | B37: =B35+B36 -> 7260 | C37: =C35+C36 -> 7260 | D37: =D35+D36 -> 7260 | E37: €
A38: Amortisation kalkulatorisch | B38: =IF(B32>0,B37/B32,"nicht erreichbar") -> 15.982006 | C38: =IF(C32>0,C37/C32,"nicht erreichbar") -> 5.3608578 | D38: =IF(D32>0,D37/D32,"nicht erreichbar") -> 5.3608578 | E38: Monate | F38: Nach wie vielen Monaten die bewertete Ersparnis alle Einmalkosten deckt.
A39: Amortisation zahlungswirksam | B39: =IF(B34>0,B35/B34,"nicht erreichbar") -> 61.689763 | C39: =IF(C34>0,C35/C34,"nicht erreichbar") -> 16.337161 | D39: =IF(D34>0,D35/D34,"nicht erreichbar") -> 16.337161 | E39: Monate | F39: Nach wie vielen Monaten die tatsächlich gesparten Auszahlungen die Einmalauszahlungen decken.
A40: Ergebnis nach Betrachtungszeitraum, kalkulatorisch | B40: =B24*B32-B37 -> 3642.2609 | C40: =C24*C32-C37 -> 25242.261 | D40: =D24*D32-D37 -> 25242.261 | E40: €
A41: Ergebnis nach Betrachtungszeitraum, zahlungswirksam | B41: =B24*B34-B35 -> -3665.7391 | C41: =C24*C34-C35 -> 2814.2609 | D41: =D24*D34-D35 -> 2814.2609 | E41: €
A42: Nettoeffekt je zusätzlichem Vorgang | B42: =(B7-B8-B9*B10)/60*B11-B12 -> 1.1904348 | C42: =(C7-C8-C9*C10)/60*C11-C12 -> 2.6904348 | D42: =(D7-D8-D9*D10)/60*D11-D12 -> 2.6904348 | E42: € | F42: Ist dieser Wert negativ, lohnt sich die Lösung bei keiner Menge.
...

Sheet Anleitung
A1: Begleit-Rechenmodell: KI wirtschaftlich einsetzen
A2: Autor: Maximilian Rosen · Preisstand 23.10.2026 · Alle Preise netto, ohne Umsatzsteuer
A4: So benutzen Sie das Modell
A5: Blaue Zahlen sind Eingaben. Ändern Sie nur diese. Schwarze Zahlen sind Formeln. Grüne Zahlen holen Werte aus einem anderen Blatt.
A6: Gelb hinterlegte Zellen sind Schlüsselannahmen, die das Ergebnis stark beeinflussen. Prüfen Sie diese zuerst für Ihr Unternehmen.
A8: Blätter
A9: Parameter: Wechselkurs, Arbeitskosten, Abo-Preise und weitere Annahmen mit Quelle.
A10: Preise: API-Preise je Million Tokens. Neue Modelle oder Anbieter tragen Sie in die freien Zeilen ein.
A11: Vorgangsrechner: Kosten eines einzelnen KI-Aufrufs und pro Monat für Ihr eigenes Szenario.
A12: Rechenbeispiele: die acht durchgerechneten Beispiele aus Kapitel 3 (Tokenökonomie), nummeriert wie im Buch.
A13: Bezugsmodelle: Kapitel 4, Platz-Abo, API mit und ohne Cache, enthaltenes API-Guthaben, lokales Modell und Copilot.
A14: Arbeitskosten: Beispielrechnung der Arbeitskosten je geleistete Stunde aus Kapitel 5.
... A30: Kurzzeichen in Spalte F entsprechen weitgehend Anhang A des Buches; BE entspricht V_BE, Extern_Stundensatz entspricht S_extern, KV1 den Kosten eines korrekt erledigten Vorgangs.

Sheet Parameter
A1: Parameter und Annahmen
A3: Parameter | B3: Wert | C3: Einheit | D3: Quelle / Art
A4: Wechselkurs: US-Dollar je Euro | B4: 1.15 | C4: USD je 1 EUR | D4: Annahme, gerundet. EZB-Referenzkurs am 15.09.2026: 1,1539 USD. Vor Nutzung aktualisieren.
A5: Preisfaktor Batch-Verarbeitung | B5: 0.5 | C5: Faktor | D5: Anthropic: 50 % Rabatt auf Input und Output, gilt auch für Cache-Preise (https://platform.claude.com/docs/en/about-claude/pricing, abgerufen 23.10.2026)
A6: Arbeitskosten je geleistete Stunde | B6: 45 | C6: EUR/h | D6: Destatis, Pressemitteilung Nr. 148 vom 29.04.2026: Arbeitskosten 2025 je geleistete Stunde 45,00 EUR im Produzierenden Gewerbe und Dienstleistungsbereich (WZ-Abschnitte B bis S ohne O). https://www.destatis.de/DE/Presse/Pressemitteilungen/2026/04/PD26_148_624.html. Für kleine Betriebe oft niedriger, siehe Blatt Arbeitskosten.
A7: Arbeitstage je Monat | B7: 21 | C7: Tage | D7: Annahme
A8: Tokens je deutschem Wort | B8: 1.6 | C8: Tokens | D8: Annahme (Faustwert) für Modelle mit neuerem Tokenizer (Claude ab 4.7). Ältere Tokenizer: rund 1,6 / 1,3 = 1,23. Mit Token-Zähler des Anbieters an eigenen Texten messen.
A9: Wörter je Seite Fließtext | B9: 350 | C9: Wörter | D9: Annahme
A10: Rechenbeispiel 5: Tokens je Frage | B10: 100 | C10: Tokens | D10: Annahme
A11: Tokenizer: Mehr-Tokens der Modelle ab 4.7 gegenüber älteren | B11: 1.3 | C11: Faktor | D11: Anthropic: Modelle ab Version 4.7 erzeugen für denselben Text rund 30 % mehr Tokens (Preisseite, abgerufen 23.10.2026)
A12: Rechenbeispiel 8: Anteil komplexer Anfragen beim Routing | B12: 0.3 | C12: % | D12: Annahme
A13: Transkription: Preis je Audiominute | B13: 0.006 | C13: USD/min | D13: Annahme. Die OpenAI-Modellseite nennt für gpt-4o-transcribe Preise je Million Audio-Tokens (2,50 USD Input), keinen Minutenpreis. 0,006 USD/min ist ein in Sekundärquellen genannter Richtwert; vor Nutzung am eigenen Audio messen.
A14: ChatGPT Business, Standard-Platz, jährliche Zahlung | B14: 20 | C14: USD/Platz/Monat | D14: OpenAI Help Center, ChatGPT Business (help.openai.com/en/articles/8792828), abgerufen im Oktober 2026; monatliche Zahlung 25 USD; Premium-Platz 100/125 USD; ab zwei Plätzen; API-Nutzung nicht enthalten
A15: Claude Team, Standard-Platz, jährliche Zahlung | B15: 20 | C15: USD/Platz/Monat | D15: https://claude.com/pricing (abgerufen 23.10.2026); monatliche Zahlung 25 USD; Premium-Platz 100/125 USD
... A26: Umsatzsteuer-Regelsatz (nur zur Information) | B26: 0.19 | C26: % | D26: § 12 Abs. 1 UStG. Das Modell rechnet netto, weil vorsteuerabzugsberechtigte Unternehmen die Umsatzsteuer nicht als Kosten tragen.

Sheet Preise
A1: API-Preise je 1 Million Tokens (USD, netto)
A2: Quellen: Anthropic https://platform.claude.com/docs/en/about-claude/pricing und OpenAI-Modellseiten (siehe Hinweis), abgerufen am 23.10.2026. Momentaufnahme. Tokenizer der Anbieter unterscheiden sich; Kosten je Vorgang an eigenen Dokumenten vergleichen.
A4: Modell | B4: Input | C4: Output | D4: Cache schreiben 5 min | E4: Cache schreiben 1 h | F4: Cache-Treffer | G4: Tokenizer | H4: Hinweis
A5: Claude Haiku 5.5 | B5: 0.1 | C5: 0.5 | D5: 0.125 | E5: 0.2 | F5: 0.01 | G5: neu | H5: nur für Prompts bis 100.000 Tokens
A6: Claude Haiku 5.5 >100k | B6: 0.5 | C6: 2.5 | D6: 0.625 | E6: 1 | F6: 0.05 | G6: neu | H6: Prompt über 100.000 Tokens: gesamter Aufruf zum höheren Preis, auch Cache-Anteile
A7: Claude Sonnet 5.5 | B7: 2 | C7: 10 | D7: 2.5 | E7: 4 | F7: 0.1 | G7: neu
A8: Claude Opus 5.5 | B8: 4 | C8: 20 | D8: 5 | E8: 8 | F8: 0.2 | G8: neu
A9: Claude Fable 5.1 | B9: 10 | C9: 50 | D9: 12.5 | E9: 20 | F9: 0.25 | G9: neu | H9: Spitzenmodell; Cache-Lesen ein Vierzigstel des Input-Preises
A10: Claude Sonnet 4.6 | B10: 3 | C10: 15 | D10: 3.75 | E10: 6 | F10: 0.3 | G10: alt | H10: älterer Tokenizer: Modelle ab Version 4.7 erzeugen für denselben Text rund 30 % mehr Tokens; umgekehrt ergibt der ältere Tokenizer rund 23 % weniger (Faktor 1/1,3)
A11: Claude Haiku 4.5 | B11: 1 | C11: 5 | D11: 1.25 | E11: 2 | F11: 0.1 | G11: alt | H11: älterer Tokenizer
A12: GPT-6 Luna | B12: 0.1 | C12: 0.5 | D12: 0.125 | E12: 0 | F12: 0.01 | G12: ? | H12: OpenAI, https://developers.openai.com/api/docs/models/gpt-6-luna (abgerufen 23.10.2026); Cache-Schreiben ohne dokumentierte 1-h-Stufe; Prompt über 272.000 Tokens: Input und Cache 2-fach, Output 1,5-fach
A13: GPT-6 Luna >272k | B13: 0.2 | C13: 0.75 | D13: 0.25 | E13: 0 | F13: 0.02 | G13: ? | H13: Preisstufe für Prompts über 272.000 Tokens, gilt für den ganzen Aufruf
A14: GPT-6.1 Sol | B14: 2 | C14: 10 | D14: 2.5 | E14: 0 | F14: 0.1 | G14: ? | H14: OpenAI, https://developers.openai.com/api/docs/models/gpt-6.1-sol (abgerufen 23.10.2026); Batch und Flex 50 % günstiger; regionale Verarbeitung +10 %
A15: GPT-6.1 Sol >272k | B15: 4 | C15: 15 | D15: 5 | E15: 0 | F15: 0.2 | G15: ? | H15: Preisstufe für Prompts über 272.000 Tokens
A16: Eigenes Modell 1 | B16: 0 | C16: 0 | D16: 0 | E16: 0 | F16: 0 | H16: freie Zeile für weitere Anbieter
A17: Eigenes Modell 2 | B17: 0 | C17: 0 | D17: 0 | E17: 0 | F17: 0 | H17: freie Zeile für weitere Anbieter

Sheet Vorgangsrechner
A1: Vorgangsrechner: Was kostet ein KI-Aufruf?
A2: Tragen Sie die Werte eines typischen Aufrufs ein. Token-Zahlen erhalten Sie aus der Nutzungsanzeige des Anbieters oder per Token-Zähler.
A4: Modell | B4: Claude Sonnet 5.5 | C4: Auswahl aus Blatt Preise
A5: Input-Tokens zum normalen Preis | B5: 3000 | C5: Anweisungen, Dokumente, Frage, soweit nicht aus dem Cache
A6: zusätzlich: in Cache geschrieben (5 min) | B6: 0 | C6: nicht in der Zeile darüber enthalten; 1,25-facher Input-Preis
A7: zusätzlich: in Cache geschrieben (1 h) | B7: 0 | C7: nicht in den Zeilen darüber enthalten; 2-facher Input-Preis
A8: zusätzlich: aus dem Cache gelesen | B8: 0 | C8: nicht in den Zeilen darüber enthalten; Bruchteil des Input-Preises
A9: Output-Tokens | B9: 500 | C9: Länge der Antwort; Output ist der teuerste Posten
A10: Aufrufe je Monat | B10: 1000
A11: Batch-Verarbeitung | B11: Nein | C11: Ja = asynchron, Ergebnis später, halber Preis
A12: Abgerechnete Preisstufe (automatisch) | B12: =IF(AND(B4="Claude Haiku 5.5",B5+B6+B7+B8>100000),"Claude Haiku 5.5 >100k",IF(AND(B4="GPT-6 Luna",B5+B6+B7+B8>272000),"GPT-6 Luna >272k",IF(AND(B4="GPT-6.1 Sol",B5+B6+B7+B8>272000),"GPT-6.1 Sol >272k",B4))) -> Claude Sonnet 5.5
A13: Kosten je Aufruf (USD) | B13: =(B5*INDEX(Preise!$B$5:$B$17,MATCH(B12,Preise!$A$5:$A$17,0))+B6*INDEX(Preise!$D$5:$D$17,MATCH(B12,Preise!$A$5:$A$17,0))+B7*INDEX(Preise!$E$5:$E$17,MATCH(B12,Preise!$A$5:$A$17,0))+B8*INDEX(Preise!$F$5:$F$17,MATCH(B12,Preise!$A$5:$A$17,0))+(B9+B19)*INDEX(Preise!$C$5:$C$17,MATCH(B12,Preise!$A$5:$A$17,0)))/1000000*IF(B11="Ja",Batchfaktor,1) -> 0.011
A14: Kosten je Aufruf (EUR) | B14: =B13/USD_je_EUR -> 0.0095652174
A15: Kosten je Monat (EUR) | B15: =B14*B10 -> 9.5652174
A16: Anteil Output an den Kosten | B16: =IF(B13=0,0,(B9+B19)*INDEX(Preise!$C$5:$C$17,MATCH(B12,Preise!$A$5:$A$17,0))/1000000*IF(B11="Ja",Batchfaktor,1)/B13) -> 0.45454545
A17: Hinweis | B17: =IF(B12<>B4,"Langer Prompt: höhere Preisstufe wird angewendet","")
A19: zusätzlich: Denk-Tokens je Aufruf | B19: 0 | C19: als Output abgerechnet; bei Generation 5.5 standardmäßig an. 0 = Denken abgeschaltet oder vernachlässigbar (Haiku 5.5: disabled; Sonnet 5.5: between_tools ohne Werkzeuge)

Sheet Rechenbeispiele
A1: Rechenbeispiele aus Kapitel 3: Tokenökonomie
A2: Preise: Blatt Preise (Stand 23.10.2026). Token-Mengen sind Annahmen für typische Aufgaben, keine Messwerte. Summenzeilen sind grau.
A4: Beispiel | B4: Variante | C4: Modell | D4: Input ohne Cache | E4: Cache schreiben 5 min | F4: Cache schreiben 1 h | G4: Cache-Treffer | H4: Output | I4: Aufrufe je Monat | J4: Batch | K4: Kosten je Aufruf (USD) | L4: Kosten je Monat (USD) | M4: Kosten je Monat (EUR) | N4: Erläuterung
A5: 1 | B5: Ein einzelner Aufruf | C5: Claude Sonnet 5.5 | D5: 1200 | E5: 0 | F5: 0 | G5: 0 | H5: 400 | I5: 1 | J5: Nein | K5: =(D5*INDEX(Preise!$B$5:$B$17,MATCH(C5,Preise!$A$5:$A$17,0))+E5*INDEX(Preise!$D$5:$D$17,MATCH(C5,Preise!$A$5:$A$17,0))+F5*INDEX(Preise!$E$5:$E$17,MATCH(C5,Preise!$A$5:$A$17,0))+G5*INDEX(Preise!$F$5:$F$17,MATCH(C5,Preise!$A$5:$A$17,0))+H5*INDEX(Preise!$C$5:$C$17,MATCH(C5,Preise!$A$5:$A$17,0)))/1000000*IF(J5="Ja",Batchfaktor,1) -> 0.0064 | L5: =K5*I5 -> 0.0064 | M5: =L5/USD_je_EUR -> 0.0055652174 | N5: Kurze Anfrage mit kurzer Antwort: kaum messbare Kosten.
A6: 1 | B6: 50 Aufrufe je Arbeitstag | C6: Claude Sonnet 5.5 | D6: 1200 | E6: 0 | F6: 0 | G6: 0 | H6: 400 | I6: =50*Arbeitstage -> 1050 | J6: Nein | K6: =(D6*INDEX(Preise!$B$5:$B$17,MATCH(C6,Preise!$A$5:$A$17,0))+E6*INDEX(Preise!$D$5:$D$17,MATCH(C6,Preise!$A$5:$A$17,0))+F6*INDEX(Preise!$E$5:$E$17,MATCH(C6,Preise!$A$5:$A$17,0))+G6*INDEX(Preise!$F$5:$F$17,MATCH(C6,Preise!$A$5:$A$17,0))+H6*INDEX(Preise!$C$5:$C$17,MATCH(C6,Preise!$A$5:$A$17,0)))/1000000*IF(J6="Ja",Batchfaktor,1) -> 0.0064 | L6: =K6*I6 -> 6.72 | M6: =L6/USD_je_EUR -> 5.8434783 | N6: Derselbe Prompt in einem kleinen Team.
A7: 1 | B7: 2.000 Aufrufe je Arbeitstag | C7: Claude Sonnet 5.5 | D7: 1200 | E7: 0 | F7: 0 | G7: 0 | H7: 400 | I7: =2000*Arbeitstage -> 42000 | J7: Nein | K7: =(D7*INDEX(Preise!$B$5:$B$17,MATCH(C7,Preise!$A$5:$A$17,0))+E7*INDEX(Preise!$D$5:$D$17,MATCH(C7,Preise!$A$5:$A$17,0))+F7*INDEX(Preise!$E$5:$E$17,MATCH(C7,Preise!$A$5:$A$17,0))+G7*INDEX(Preise!$F$5:$F$17,MATCH(C7,Preise!$A$5:$A$17,0))+H7*INDEX(Preise!$C$5:$C$17,MATCH(C7,Preise!$A$5:$A$17,0)))/1000000*IF(J7="Ja",Batchfaktor,1) -> 0.0064 | L7: =K7*I7 -> 268.8 | M7: =L7/USD_je_EUR -> 233.73913 | N7: Derselbe Prompt in einer automatisierten Verarbeitung.
A8: 2 | B8: Kurze Antwort (300 Tokens) | C8: Claude Sonnet 5.5 | D8: 2000 | E8: 0 | F8: 0 | G8: 0 | H8: 300 | I8: 3000 | J8: Nein | K8: =(D8*INDEX(Preise!$B$5:$B$17,MATCH(C8,Preise!$A$5:$A$17,0))+E8*INDEX(Preise!$D$5:$D$17,MATCH(C8,Preise!$A$5:$A$17,0))+F8*INDEX(Preise!$E$5:$E$17,MATCH(C8,Preise!$A$5:$A$17,0))+G8*INDEX(Preise!$F$5:$F$17,MATCH(C8,Preise!$A$5:$A$17,0))+H8*INDEX(Preise!$C$5:$C$17,MATCH(C8,Preise!$A$5:$A$17,0)))/1000000*IF(J8="Ja",Batchfaktor,1) -> 0.007 | L8: =K8*I8 -> 21 | M8: =L8/USD_je_EUR -> 18.26087 | N8: Gleiche Aufgabe, Antwort auf das Nötige begrenzt.
A9: 2 | B9: Ausführliche Antwort (1.500 Tokens) | C9: Claude Sonnet 5.5 | D9: 2000 | E9: 0 | F9: 0 | G9: 0 | H9: 1500 | I9: 3000 | J9: Nein | K9: =(D9*INDEX(Preise!$B$5:$B$17,MATCH(C9,Preise!$A$5:$A$17,0))+E9*INDEX(Preise!$D$5:$D$17,MATCH(C9,Preise!$A$5:$A$17,0))+F9*INDEX(Preise!$E$5:$E$17,MATCH(C9,Preise!$A$5:$A$17,0))+G9*INDEX(Preise!$F$5:$F$17,MATCH(C9,Preise!$A$5:$A$17,0))+H9*INDEX(Preise!$C$5:$C$17,MATCH(C9,Preise!$A$5:$A$17,0)))/1000000*IF(J9="Ja",Batchfaktor,1) -> 0.019 | L9: =K9*I9 -> 57 | M9: =L9/USD_je_EUR -> 49.565217 | N9: Output kostet je Token das Fünffache des Inputs.
A10: 3 | B10: Prompt 99.000 Tokens | C10: Claude Haiku 5.5 | D10: 99000 | E10: 0 | F10: 0 | G10: 0 | H10: 1000 | I10: 1 | J10: Nein | K10: =(D10*INDEX(Preise!$B$5:$B$17,MATCH(C10,Preise!$A$5:$A$17,0))+E10*INDEX(Preise!$D$5:$D$17,MATCH(C10,Preise!$A$5:$A$17,0))+F10*INDEX(Preise!$E$5:$E$17,MATCH(C10,Preise!$A$5:$A$17,0))+G10*INDEX(Preise!$F$5:$F$17,MATCH(C10,Preise!$A$5:$A$17,0))+H10*INDEX(Preise!$C$5:$C$17,MATCH(C10,Preise!$A$5:$A$17,0)))/1000000*IF(J10="Ja",Batchfaktor,1) -> 0.0104 | L10: =K10*I10 -> 0.0104 | M10: =L10/USD_je_EUR -> 0.0090434783 | N10: Knapp unter der Preisschwelle.
A11: 3 | B11: Prompt 101.000 Tokens | C11: Claude Haiku 5.5 >100k | D11: 101000 | E11: 0 | F11: 0 | G11: 0 | H11: 1000 | I11: 1 | J11: Nein | K11: =(D11*INDEX(Preise!$B$5:$B$17,MATCH(C11,Preise!$A$5:$A$17,0))+E11*INDEX(Preise!$D$5:$D$17,MATCH(C11,Preise!$A$5:$A$17,0))+F11*INDEX(Preise!$E$5:$E$17,MATCH(C11,Preise!$A$5:$A$17,0))+G11*INDEX(Preise!$F$5:$F$17,MATCH(C11,Preise!$A$5:$A$17,0))+H11*INDEX(Preise!$C$5:$C$17,MATCH(C11,Preise!$A$5:$A$17,0)))/1000000*IF(J11="Ja",Batchfaktor,1) -> 0.053 | L11: =K11*I11 -> 0.053 | M11: =L11/USD_je_EUR -> 0.046086957 | N11: 2 % mehr Input, gesamter Aufruf zum fünffachen Preis.
A12: 4 | B12: Vorgänger, älterer Tokenizer | C12: Claude Sonnet 4.6 | D12: =ROUND(10000*Token_je_Wort/Tokenizer_Faktor_alt,-2) -> 12300 | E12: 0 | F12: 0 | G12: 0 | H12: 0 | I12: 1 | J12: Nein | K12: =(D12*INDEX(Preise!$B$5:$B$17,MATCH(C12,Preise!$A$5:$A$17,0))+E12*INDEX(Preise!$D$5:$D$17,MATCH(C12,Preise!$A$5:$A$17,0))+F12*INDEX(Preise!$E$5:$E$17,MATCH(C12,Preise!$A$5:$A$17,0))+G12*INDEX(Preise!$F$5:$F$17,MATCH(C12,Preise!$A$5:$A$17,0))+H12*INDEX(Preise!$C$5:$C$17,MATCH(C12,Preise!$A$5:$A$17,0)))/1000000*IF(J12="Ja",Batchfaktor,1) -> 0.0369 | L12: =K12*I12 -> 0.0369 | M12: =L12/USD_je_EUR -> 0.032086957 | N12: 10.000 Wörter Input; der ältere Tokenizer erzeugt 1/1,3 der Tokens des neueren, also rund 23 % weniger.
A13: 4 | B13: Nachfolger, neuerer Tokenizer (+30 %) | C13: Claude Sonnet 5.5 | D13: =ROUND(10000*Token_je_Wort,-2) -> 16000 | E13: 0 | F13: 0 | G13: 0 | H13: 0 | I13: 1 | J13: Nein | K13: =(D13*INDEX(Preise!$B$5:$B$17,MATCH(C13,Preise!$A$5:$A$17,0))+E13*INDEX(Preise!$D$5:$D$17,MATCH(C13,Preise!$A$5:$A$17,0))+F13*INDEX(Preise!$E$5:$E$17,MATCH(C13,Preise!$A$5:$A$17,0))+G13*INDEX(Preise!$F$5:$F$17,MATCH(C13,Preise!$A$5:$A$17,0))+H13*INDEX(Preise!$C$5:$C$17,MATCH(C13,Preise!$A$5:$A$17,0)))/1000000*IF(J13="Ja",Batchfaktor,1) -> 0.032 | L13: =K13*I13 -> 0.032 | M13: =L13/USD_je_EUR -> 0.027826087 | N13: Gleicher Text, laut Anbieter rund 30 % mehr Tokens. Listenpreis −33 %, tatsächliche Kosten nur rund −13 %.
A14: 5 | B14: Handbuch bei jeder Frage, ohne Cache | C14: Claude Sonnet 5.5 | D14: =ROUND(80*Woerter_je_Seite*Token_je_Wort,-3)+Tokens_je_Frage -> 45100 | E14: 0 | F14: 0 | G14: 0 | H14: 400 | I14: =20*Arbeitstage -> 420 | J14: Nein | K14: =(D14*INDEX(Preise!$B$5:$B$17,MATCH(C14,Preise!$A$5:$A$17,0))+E14*INDEX(Preise!$D$5:$D$17,MATCH(C14,Preise!$A$5:$A$17,0))+F14*INDEX(Preise!$E$5:$E$17,MATCH(C14,Preise!$A$5:$A$17,0))+G14*INDEX(Preise!$F$5:$F$17,MATCH(C14,Preise!$A$5:$A$17,0))+H14*INDEX(Preise!$C$5:$C$17,MATCH(C14,Preise!$A$5:$A$17,0)))/1000000*IF(J14="Ja",Batchfaktor,1) -> 0.0942 | L14: =K14*I14 -> 39.564 | M14: =L14/USD_je_EUR -> 34.403478 | N14: 80 Seiten Handbuch plus Frage, 20 Fragen je Tag, Abstand rund 24 Minuten.
A15: 5 | B15: 5-min-Cache bei 24 min Abstand | C15: Claude Sonnet 5.5 | D15: =Tokens_je_Frage -> 100 | E15: =ROUND(80*Woerter_je_Seite*Token_je_Wort,-3) -> 45000 | F15: 0 | G15: 0 | H15: 400 | I15: =20*Arbeitstage -> 420 | J15: Nein | K15: =(D15*INDEX(Preise!$B$5:$B$17,MATCH(C15,Preise!$A$5:$A$17,0))+E15*INDEX(Preise!$D$5:$D$17,MATCH(C15,Preise!$A$5:$A$17,0))+F15*INDEX(Preise!$E$5:$E$17,MATCH(C15,Preise!$A$5:$A$17,0))+G15*INDEX(Preise!$F$5:$F$17,MATCH(C15,Preise!$A$5:$A$17,0))+H15*INDEX(Preise!$C$5:$C$17,MATCH(C15,Preise!$A$5:$A$17,0)))/1000000*IF(J15="Ja",Batchfaktor,1) -> 0.1167 | L15: =K15*I15 -> 49.014 | M15: =L15/USD_je_EUR -> 42.62087 | N15: Cache läuft zwischen zwei Fragen ab: jeder Aufruf schreibt neu und zahlt 25 % Aufschlag.
A16: 5 | B16: 1-h-Cache: erster Aufruf am Tag | C16: Claude Sonnet 5.5 | D16: =Tokens_je_Frage -> 100 | E16: 0 | F16: =ROUND(80*Woerter_je_Seite*Token_je_Wort,-3) -> 45000 | G16: 0 | H16: 400 | I16: =Arbeitstage -> 21 | J16: Nein | K16: =(D16*INDEX(Preise!$B$5:$B$17,MATCH(C16,Preise!$A$5:$A$17,0))+E16*INDEX(Preise!$D$5:$D$17,MATCH(C16,Preise!$A$5:$A$17,0))+F16*INDEX(Preise!$E$5:$E$17,MATCH(C16,Preise!$A$5:$A$17,0))+G16*INDEX(Preise!$F$5:$F$17,MATCH(C16,Preise!$A$5:$A$17,0))+H16*INDEX(Preise!$C$5:$C$17,MATCH(C16,Preise!$A$5:$A$17,0)))/1000000*IF(J16="Ja",Batchfaktor,1) -> 0.1842 | L16: =K16*I16 -> 3.8682 | M16: =L16/USD_je_EUR -> 3.3636522 | N16: Einmal täglich schreiben (2-facher Input-Preis).
A17: 5 | B17: 1-h-Cache: Folgeaufrufe | C17: Claude Sonnet 5.5 | D17: =Tokens_je_Frage -> 100 | E17: 0 | F17: 0 | G17: =ROUND(80*Woerter_je_Seite*Token_je_Wort,-3) -> 45000 | H17: 400 | I17: =19*Arbeitstage -> 399 | J17: Nein | K17: =(D17*INDEX(Preise!$B$5:$B$17,MATCH(C17,Preise!$A$5:$A$17,0))+E17*INDEX(Preise!$D$5:$D$17,MATCH(C17,Preise!$A$5:$A$17,0))+F17*INDEX(Preise!$E$5:$E$17,MATCH(C17,Preise!$A$5:$A$17,0))+G17*INDEX(Preise!$F$5:$F$17,MATCH(C17,Preise!$A$5:$A$17,0))+H17*INDEX(Preise!$C$5:$C$17,MATCH(C17,Preise!$A$5:$A$17,0)))/1000000*IF(J17="Ja",Batchfaktor,1) -> 0.0087 | L17: =K17*I17 -> 3.4713 | M17: =L17/USD_je_EUR -> 3.0185217 | N17: Treffer verlängern den Cache; Annahme: keine Pause über 60 Minuten.
B18: Summe 1-h-Cache | L18: =SUM(L16:L17) -> 7.3395 | M18: =SUM(M16:M17) -> 6.3821739 | N18: Variante mit 1-h-Cache gesamt.
A19: 5 | B19: Nur passende Abschnitte (RAG) | C19: Claude Sonnet 5.5 | D19: =4000+Tokens_je_Frage -> 4100 | E19: 0 | F19: 0 | G19: 0 | H19: 400 | I19: =20*Arbeitstage -> 420 | J19: Nein | K19: =(D19*INDEX(Preise!$B$5:$B$17,MATCH(C19,Preise!$A$5:$A$17,0))+E19*INDEX(Preise!$D$5:$D$17,MATCH(C19,Preise!$A$5:$A$17,0))+F19*INDEX(Preise!$E$5:$E$17,MATCH(C19,Preise!$A$5:$A$17,0))+G19*INDEX(Preise!$F$5:$F$17,MATCH(C19,Preise!$A$5:$A$17,0))+H19*INDEX(Preise!$C$5:$C$17,MATCH(C19,Preise!$A$5:$A$17,0)))/1000000*IF(J19="Ja",Batchfaktor,1) -> 0.0122 | L19: =K19*I19 -> 5.124 | M19: =L19/USD_je_EUR -> 4.4556522 | N19: Suche liefert rund 4.000 Tokens passender Textstellen; Kosten für Suche und Index nicht enthalten.
A20: 6 | B20: Sofortverarbeitung, kleines Modell | C20: Claude Haiku 5.5 | D20: 3500 | E20: 0 | F20: 0 | G20: 0 | H20: 400 | I20: 2000 | J20: Nein | K20: =(D20*INDEX(Preise!$B$5:$B$17,MATCH(C20,Preise!$A$5:$A$17,0))+E20*INDEX(Preise!$D$5:$D$17,MATCH(C20,Preise!$A$5:$A$17,0))+F20*INDEX(Preise!$E$5:$E$17,MATCH(C20,Preise!$A$5:$A$17,0))+G20*INDEX(Preise!$F$5:$F$17,MATCH(C20,Preise!$A$5:$A$17,0))+H20*INDEX(Preise!$C$5:$C$17,MATCH(C20,Preise!$A$5:$A$17,0)))/1000000*IF(J20="Ja",Batchfaktor,1) -> 0.00055 | L20: =K20*I20 -> 1.1 | M20: =L20/USD_je_EUR -> 0.95652174 | N20: Datenauszug aus 2.000 Dokumenten je Monat.
A21: 6 | B21: Batch, kleines Modell | C21: Claude Haiku 5.5 | D21: 3500 | E21: 0 | F21: 0 | G21: 0 | H21: 400 | I21: 2000 | J21: Ja | K21: =(D21*INDEX(Preise!$B$5:$B$17,MATCH(C21,Preise!$A$5:$A$17,0))+E21*INDEX(Preise!$D$5:$D$17,MATCH(C21,Preise!$A$5:$A$17,0))+F21*INDEX(Preise!$E$5:$E$17,MATCH(C21,Preise!$A$5:$A$17,0))+G21*INDEX(Preise!$F$5:$F$17,MATCH(C21,Preise!$A$5:$A$17,0))+H21*INDEX(Preise!$C$5:$C$17,MATCH(C21,Preise!$A$5:$A$17,0)))/1000000*IF(J21="Ja",Batchfaktor,1) -> 0.000275 | L21: =K21*I21 -> 0.55 | M21: =L21/USD_je_EUR -> 0.47826087 | N21: Halber Preis; absolute Ersparnis sehr klein.
A22: 6 | B22: Sofortverarbeitung, mittleres Modell | C22: Claude Sonnet 5.5 | D22: 3500 | E22: 0 | F22: 0 | G22: 0 | H22: 400 | I22: 2000 | J22: Nein | K22: =(D22*INDEX(Preise!$B$5:$B$17,MATCH(C22,Preise!$A$5:$A$17,0))+E22*INDEX(Preise!$D$5:$D$17,MATCH(C22,Preise!$A$5:$A$17,0))+F22*INDEX(Preise!$E$5:$E$17,MATCH(C22,Preise!$A$5:$A$17,0))+G22*INDEX(Preise!$F$5:$F$17,MATCH(C22,Preise!$A$5:$A$17,0))+H22*INDEX(Preise!$C$5:$C$17,MATCH(C22,Preise!$A$5:$A$17,0)))/1000000*IF(J22="Ja",Batchfaktor,1) -> 0.011 | L22: =K22*I22 -> 22 | M22: =L22/USD_je_EUR -> 19.130435
A23: 6 | B23: Batch, mittleres Modell | C23: Claude Sonnet 5.5 | D23: 3500 | E23: 0 | F23: 0 | G23: 0 | H23: 400 | I23: 2000 | J23: Ja | K23: =(D23*INDEX(Preise!$B$5:$B$17,MATCH(C23,Preise!$A$5:$A$17,0))+E23*INDEX(Preise!$D$5:$D$17,MATCH(C23,Preise!$A$5:$A$17,0))+F23*INDEX(Preise!$E$5:$E$17,MATCH(C23,Preise!$A$5:$A$17,0))+G23*INDEX(Preise!$F$5:$F$17,MATCH(C23,Preise!$A$5:$A$17,0))+H23*INDEX(Preise!$C$5:$C$17,MATCH(C23,Preise!$A$5:$A$17,0)))/1000000*IF(J23="Ja",Batchfaktor,1) -> 0.0055 | L23: =K23*I23 -> 11 | M23: =L23/USD_je_EUR -> 9.5652174
A24: 7 | B24: Tabelle komplett im Prompt | C24: Claude Sonnet 5.5 | D24: 500000 | E24: 0 | F24: 0 | G24: 0 | H24: 1500 | I24: 20 | J24: Nein | K24: =(D24*INDEX(Preise!$B$5:$B$17,MATCH(C24,Preise!$A$5:$A$17,0))+E24*INDEX(Preise!$D$5:$D$17,MATCH(C24,Preise!$A$5:$A$17,0))+F24*INDEX(Preise!$E$5:$E$17,MATCH(C24,Preise!$A$5:$A$17,0))+G24*INDEX(Preise!$F$5:$F$17,MATCH(C24,Preise!$A$5:$A$17,0))+H24*INDEX(Preise!$C$5:$C$17,MATCH(C24,Preise!$A$5:$A$17,0)))/1000000*IF(J24="Ja",Batchfaktor,1) -> 1.015 | L24: =K24*I24 -> 20.3 | M24: =L24/USD_je_EUR -> 17.652174 | N24: 20.000 Zeilen mit je rund 25 Tokens; Rechnen im Modell ist zudem fehleranfällig.
A25: 7 | B25: Nur Spalten und Stichprobe, Modell schreibt Code | C25: Claude Sonnet 5.5 | D25: 3000 | E25: 0 | F25: 0 | G25: 0 | H25: 800 | I25: 20 | J25: Nein | K25: =(D25*INDEX(Preise!$B$5:$B$17,MATCH(C25,Preise!$A$5:$A$17,0))+E25*INDEX(Preise!$D$5:$D$17,MATCH(C25,Preise!$A$5:$A$17,0))+F25*INDEX(Preise!$E$5:$E$17,MATCH(C25,Preise!$A$5:$A$17,0))+G25*INDEX(Preise!$F$5:$F$17,MATCH(C25,Preise!$A$5:$A$17,0))+H25*INDEX(Preise!$C$5:$C$17,MATCH(C25,Preise!$A$5:$A$17,0)))/1000000*IF(J25="Ja",Batchfaktor,1) -> 0.014 | L25: =K25*I25 -> 0.28 | M25: =L25/USD_je_EUR -> 0.24347826 | N25: Berechnung läuft in Python oder SQL außerhalb des Modells.
A26: 8 | B26: Alles mit mittlerem Modell | C26: Claude Sonnet 5.5 | D26: 2500 | E26: 0 | F26: 0 | G26: 0 | H26: 500 | I26: 3000 | J26: Nein | K26: =(D26*INDEX(Preise!$B$5:$B$17,MATCH(C26,Preise!$A$5:$A$17,0))+E26*INDEX(Preise!$D$5:$D$17,MATCH(C26,Preise!$A$5:$A$17,0))+F26*INDEX(Preise!$E$5:$E$17,MATCH(C26,Preise!$A$5:$A$17,0))+G26*INDEX(Preise!$F$5:$F$17,MATCH(C26,Preise!$A$5:$A$17,0))+H26*INDEX(Preise!$C$5:$C$17,MATCH(C26,Preise!$A$5:$A$17,0)))/1000000*IF(J26="Ja",Batchfaktor,1) -> 0.01 | L26: =K26*I26 -> 30 | M26: =L26/USD_je_EUR -> 26.086957 | N26: Kundenanfragen einordnen und Antwort entwerfen.
A27: 8 | B27: Alles mit großem Modell | C27: Claude Opus 5.5 | D27: 2500 | E27: 0 | F27: 0 | G27: 0 | H27: 500 | I27: 3000 | J27: Nein | K27: =(D27*INDEX(Preise!$B$5:$B$17,MATCH(C27,Preise!$A$5:$A$17,0))+E27*INDEX(Preise!$D$5:$D$17,MATCH(C27,Preise!$A$5:$A$17,0))+F27*INDEX(Preise!$E$5:$E$17,MATCH(C27,Preise!$A$5:$A$17,0))+G27*INDEX(Preise!$F$5:$F$17,MATCH(C27,Preise!$A$5:$A$17,0))+H27*INDEX(Preise!$C$5:$C$17,MATCH(C27,Preise!$A$5:$A$17,0)))/1000000*IF(J27="Ja",Batchfaktor,1) -> 0.02 | L27: =K27*I27 -> 60 | M27: =L27/USD_je_EUR -> 52.173913
A28: 8 | B28: Routing: Einordnung kleines Modell | C28: Claude Haiku 5.5 | D28: 2500 | E28: 0 | F28: 0 | G28: 0 | H28: 50 | I28: 3000 | J28: Nein | K28: =(D28*INDEX(Preise!$B$5:$B$17,MATCH(C28,Preise!$A$5:$A$17,0))+E28*INDEX(Preise!$D$5:$D$17,MATCH(C28,Preise!$A$5:$A$17,0))+F28*INDEX(Preise!$E$5:$E$17,MATCH(C28,Preise!$A$5:$A$17,0))+G28*INDEX(Preise!$F$5:$F$17,MATCH(C28,Preise!$A$5:$A$17,0))+H28*INDEX(Preise!$C$5:$C$17,MATCH(C28,Preise!$A$5:$A$17,0)))/1000000*IF(J28="Ja",Batchfaktor,1) -> 0.000275 | L28: =K28*I28 -> 0.825 | M28: =L28/USD_je_EUR -> 0.7173913 | N28: Jede Anfrage wird zuerst eingeordnet.
A29: 8 | B29: Routing: 30 % komplexe Fälle | C29: Claude Sonnet 5.5 | D29: 2500 | E29: 0 | F29: 0 | G29: 0 | H29: 500 | I29: =3000*Routing_Anteil_komplex -> 900 | J29: Nein | K29: =(D29*INDEX(Preise!$B$5:$B$17,MATCH(C29,Preise!$A$5:$A$17,0))+E29*INDEX(Preise!$D$5:$D$17,MATCH(C29,Preise!$A$5:$A$17,0))+F29*INDEX(Preise!$E$5:$E$17,MATCH(C29,Preise!$A$5:$A$17,0))+G29*INDEX(Preise!$F$5:$F$17,MATCH(C29,Preise!$A$5:$A$17,0))+H29*INDEX(Preise!$C$5:$C$17,MATCH(C29,Preise!$A$5:$A$17,0)))/1000000*IF(J29="Ja",Batchfaktor,1) -> 0.01 | L29: =K29*I29 -> 9 | M29: =L29/USD_je_EUR -> 7.826087
A30: 8 | B30: Routing: 70 % einfache Fälle | C30: Claude Haiku 5.5 | D30: 2500 | E30: 0 | F30: 0 | G30: 0 | H30: 500 | I30: =3000*(1-Routing_Anteil_komplex) -> 2100 | J30: Nein | K30: =(D30*INDEX(Preise!$B$5:$B$17,MATCH(C30,Preise!$A$5:$A$17,0))+E30*INDEX(Preise!$D$5:$D$17,MATCH(C30,Preise!$A$5:$A$17,0))+F30*INDEX(Preise!$E$5:$E$17,MATCH(C30,Preise!$A$5:$A$17,0))+G30*INDEX(Preise!$F$5:$F$17,MATCH(C30,Preise!$A$5:$A$17,0))+H30*INDEX(Preise!$C$5:$C$17,MATCH(C30,Preise!$A$5:$A$17,0)))/1000000*IF(J30="Ja",Batchfaktor,1) -> 0.0005 | L30: =K30*I30 -> 1.05 | M30: =L30/USD_je_EUR -> 0.91304348
B31: Summe Routing | L31: =SUM(L28:L30) -> 10.875 | M31: =SUM(M28:M30) -> 9.4565217 | N31: Tokenkosten der Routing-Variante. Nacharbeit siehe Block unten.
A33: Beispiel 8, Gesamtsystem: Was kostet Nacharbeit?
B34: Fälle mit kleinem Modell je Monat | C34: =3000*(1-Routing_Anteil_komplex) -> 2100
B35: Zusätzliche Nacharbeitsquote gegenüber mittlerem Modell | C35: 0.1
B36: Minuten Nacharbeit je betroffenem Fall | C36: 1
B37: Kosten Nacharbeit je Monat (EUR) | C37: =C34*C35*C36/60*Stundensatz -> 157.5
B38: Tokenersparnis Routing gegenüber mittlerem Modell (EUR) | C38: =M26-M31 -> 16.630435
B39: Netto-Effekt des Routings (EUR je Monat) | C39: =C38-C37 -> -140.86957 | D39: Negativ = Routing spart Tokens, kostet aber mehr Arbeitszeit, als es spart.
A41: Kennzahlen aus dem Text (Kapitel 3)
B42: RB 1: Anteil Output an den Kosten | C42: =H5*INDEX(Preise!$C$5:$C$17,MATCH(C5,Preise!$A$5:$A$17,0))/1000000/K5 -> 0.625
B43: RB 2: Faktor ausführlich / kurz | C43: =K9/K8 -> 2.7142857
...

Sheet Bezugsmodelle
A1: Kapitel 4: Platz-Abo, API oder lokales Modell?
A2: Vergleich nur für dieselbe Aufgabe: interaktive Arbeit einer Person mit einem Chat. Ein Platz-Abo enthält Oberfläche und Verwaltung; die API-Variante braucht eine eigene Oberfläche, deren Betreuung unten getrennt bewertet wird. Nutzungsgrenzen der Abos sind nicht in Tokens beziffert. Cache-Anteil: Anteil des Inputs, der aus dem Zwischenspeicher gelesen wird (wiederholter Gesprächsverlauf, gleiche Dokumente); der Rest wird neu in den Cache geschrieben (5 min).
A4: Nutzungsprofil | B4: Anfragen je Arbeitstag | C4: Input je Anfrage (Tokens) | D4: Output je Anfrage (Tokens) | E4: Cache-Anteil Input | F4: Modell | G4: API ohne Cache (USD/Monat) | H4: API mit Cache (USD/Monat) | I4: API mit Cache (EUR/Monat) | J4: Platzpreis jährl. (USD) | K4: Platz günstiger ab … Anfragen je Tag (mit Cache) | L4: Platz günstiger ab … (ohne Cache) | M4: Bemerkung | N4: API, halber Cache-Anteil (USD/Monat) | O4: API mit Cache und Denk-Tokens laut Parameter (USD/Monat)
A5: P1 gelegentlich | B5: 5 | C5: 3000 | D5: 600 | E5: 0 | F5: Claude Sonnet 5.5 | G5: =B5*Arbeitstage*(C5*INDEX(Preise!$B$5:$B$17,MATCH(F5,Preise!$A$5:$A$17,0))+D5*INDEX(Preise!$C$5:$C$17,MATCH(F5,Preise!$A$5:$A$17,0)))/1000000 -> 1.26 | H5: =B5*Arbeitstage*(IF(E5=0,C5*INDEX(Preise!$B$5:$B$17,MATCH(F5,Preise!$A$5:$A$17,0)),C5*(E5*INDEX(Preise!$F$5:$F$17,MATCH(F5,Preise!$A$5:$A$17,0))+(1-E5)*INDEX(Preise!$D$5:$D$17,MATCH(F5,Preise!$A$5:$A$17,0))))+D5*INDEX(Preise!$C$5:$C$17,MATCH(F5,Preise!$A$5:$A$17,0)))/1000000 -> 1.26 | I5: =H5/USD_je_EUR -> 1.0956522 | J5: =Abo_Claude_Team -> 20 | K5: =ROUNDUP(J5/((IF(E5=0,C5*INDEX(Preise!$B$5:$B$17,MATCH(F5,Preise!$A$5:$A$17,0)),C5*(E5*INDEX(Preise!$F$5:$F$17,MATCH(F5,Preise!$A$5:$A$17,0))+(1-E5)*INDEX(Preise!$D$5:$D$17,MATCH(F5,Preise!$A$5:$A$17,0))))+D5*INDEX(Preise!$C$5:$C$17,MATCH(F5,Preise!$A$5:$A$17,0)))/1000000)/Arbeitstage,0) -> 80 | L5: =ROUNDUP(J5/((C5*INDEX(Preise!$B$5:$B$17,MATCH(F5,Preise!$A$5:$A$17,0))+D5*INDEX(Preise!$C$5:$C$17,MATCH(F5,Preise!$A$5:$A$17,0)))/1000000)/Arbeitstage,0) -> 80 | M5: einzelne kurze Fragen, kaum Wiederholung | N5: =B5*Arbeitstage*(IF(E5=0,C5*INDEX(Preise!$B$5:$B$17,MATCH(F5,Preise!$A$5:$A$17,0)),C5*(E5/2*INDEX(Preise!$F$5:$F$17,MATCH(F5,Preise!$A$5:$A$17,0))+(1-E5/2)*INDEX(Preise!$D$5:$D$17,MATCH(F5,Preise!$A$5:$A$17,0))))+D5*INDEX(Preise!$C$5:$C$17,MATCH(F5,Preise!$A$5:$A$17,0)))/1000000 -> 1.26 | O5: =H5+B5*Arbeitstage*Denk_Tokens_Szenario*INDEX(Preise!$C$5:$C$17,MATCH(F5,Preise!$A$5:$A$17,0))/1000000 -> 2.31
A6: P2 regelmäßig | B6: 20 | C6: 6000 | D6: 800 | E6: 0.5 | F6: Claude Sonnet 5.5 | G6: =B6*Arbeitstage*(C6*INDEX(Preise!$B$5:$B$17,MATCH(F6,Preise!$A$5:$A$17,0))+D6*INDEX(Preise!$C$5:$C$17,MATCH(F6,Preise!$A$5:$A$17,0)))/1000000 -> 8.4 | H6: =B6*Arbeitstage*(IF(E6=0,C6*INDEX(Preise!$B$5:$B$17,MATCH(F6,Preise!$A$5:$A$17,0)),C6*(E6*INDEX(Preise!$F$5:$F$17,MATCH(F6,Preise!$A$5:$A$17,0))+(1-E6)*INDEX(Preise!$D$5:$D$17,MATCH(F6,Preise!$A$5:$A$17,0))))+D6*INDEX(Preise!$C$5:$C$17,MATCH(F6,Preise!$A$5:$A$17,0)))/1000000 -> 6.636 | I6: =H6/USD_je_EUR -> 5.7704348 | J6: =Abo_Claude_Team -> 20 | K6: =ROUNDUP(J6/((IF(E6=0,C6*INDEX(Preise!$B$5:$B$17,MATCH(F6,Preise!$A$5:$A$17,0)),C6*(E6*INDEX(Preise!$F$5:$F$17,MATCH(F6,Preise!$A$5:$A$17,0))+(1-E6)*INDEX(Preise!$D$5:$D$17,MATCH(F6,Preise!$A$5:$A$17,0))))+D6*INDEX(Preise!$C$5:$C$17,MATCH(F6,Preise!$A$5:$A$17,0)))/1000000)/Arbeitstage,0) -> 61 | L6: =ROUNDUP(J6/((C6*INDEX(Preise!$B$5:$B$17,MATCH(F6,Preise!$A$5:$A$17,0))+D6*INDEX(Preise!$C$5:$C$17,MATCH(F6,Preise!$A$5:$A$17,0)))/1000000)/Arbeitstage,0) -> 48 | M6: tägliche Arbeit mit kurzen Dokumenten | N6: =B6*Arbeitstage*(IF(E6=0,C6*INDEX(Preise!$B$5:$B$17,MATCH(F6,Preise!$A$5:$A$17,0)),C6*(E6/2*INDEX(Preise!$F$5:$F$17,MATCH(F6,Preise!$A$5:$A$17,0))+(1-E6/2)*INDEX(Preise!$D$5:$D$17,MATCH(F6,Preise!$A$5:$A$17,0))))+D6*INDEX(Preise!$C$5:$C$17,MATCH(F6,Preise!$A$5:$A$17,0)))/1000000 -> 8.148 | O6: =H6+B6*Arbeitstage*Denk_Tokens_Szenario*INDEX(Preise!$C$5:$C$17,MATCH(F6,Preise!$A$5:$A$17,0))/1000000 -> 10.836
A7: P3 intensiv mit Dokumenten | B7: 60 | C7: 15000 | D7: 1200 | E7: 0.8 | F7: Claude Sonnet 5.5 | G7: =B7*Arbeitstage*(C7*INDEX(Preise!$B$5:$B$17,MATCH(F7,Preise!$A$5:$A$17,0))+D7*INDEX(Preise!$C$5:$C$17,MATCH(F7,Preise!$A$5:$A$17,0)))/1000000 -> 52.92 | H7: =B7*Arbeitstage*(IF(E7=0,C7*INDEX(Preise!$B$5:$B$17,MATCH(F7,Preise!$A$5:$A$17,0)),C7*(E7*INDEX(Preise!$F$5:$F$17,MATCH(F7,Preise!$A$5:$A$17,0))+(1-E7)*INDEX(Preise!$D$5:$D$17,MATCH(F7,Preise!$A$5:$A$17,0))))+D7*INDEX(Preise!$C$5:$C$17,MATCH(F7,Preise!$A$5:$A$17,0)))/1000000 -> 26.082 | I7: =H7/USD_je_EUR -> 22.68 | J7: =Abo_Claude_Team -> 20 | K7: =ROUNDUP(J7/((IF(E7=0,C7*INDEX(Preise!$B$5:$B$17,MATCH(F7,Preise!$A$5:$A$17,0)),C7*(E7*INDEX(Preise!$F$5:$F$17,MATCH(F7,Preise!$A$5:$A$17,0))+(1-E7)*INDEX(Preise!$D$5:$D$17,MATCH(F7,Preise!$A$5:$A$17,0))))+D7*INDEX(Preise!$C$5:$C$17,MATCH(F7,Preise!$A$5:$A$17,0)))/1000000)/Arbeitstage,0) -> 47 | L7: =ROUNDUP(J7/((C7*INDEX(Preise!$B$5:$B$17,MATCH(F7,Preise!$A$5:$A$17,0))+D7*INDEX(Preise!$C$5:$C$17,MATCH(F7,Preise!$A$5:$A$17,0)))/1000000)/Arbeitstage,0) -> 23 | M7: Analysen, lange Gesprächsverläufe | N7: =B7*Arbeitstage*(IF(E7=0,C7*INDEX(Preise!$B$5:$B$17,MATCH(F7,Preise!$A$5:$A$17,0)),C7*(E7/2*INDEX(Preise!$F$5:$F$17,MATCH(F7,Preise!$A$5:$A$17,0))+(1-E7/2)*INDEX(Preise!$D$5:$D$17,MATCH(F7,Preise!$A$5:$A$17,0))))+D7*INDEX(Preise!$C$5:$C$17,MATCH(F7,Preise!$A$5:$A$17,0)))/1000000 -> 44.226 | O7: =H7+B7*Arbeitstage*Denk_Tokens_Szenario*INDEX(Preise!$C$5:$C$17,MATCH(F7,Preise!$A$5:$A$17,0))/1000000 -> 38.682
A8: P4 Dauernutzung, lange Dokumente | B8: 100 | C8: 40000 | D8: 1500 | E8: 0.9 | F8: Claude Sonnet 5.5 | G8: =B8*Arbeitstage*(C8*INDEX(Preise!$B$5:$B$17,MATCH(F8,Preise!$A$5:$A$17,0))+D8*INDEX(Preise!$C$5:$C$17,MATCH(F8,Preise!$A$5:$A$17,0)))/1000000 -> 199.5 | H8: =B8*Arbeitstage*(IF(E8=0,C8*INDEX(Preise!$B$5:$B$17,MATCH(F8,Preise!$A$5:$A$17,0)),C8*(E8*INDEX(Preise!$F$5:$F$17,MATCH(F8,Preise!$A$5:$A$17,0))+(1-E8)*INDEX(Preise!$D$5:$D$17,MATCH(F8,Preise!$A$5:$A$17,0))))+D8*INDEX(Preise!$C$5:$C$17,MATCH(F8,Preise!$A$5:$A$17,0)))/1000000 -> 60.06 | I8: =H8/USD_je_EUR -> 52.226087 | J8: =Abo_Claude_Team -> 20 | K8: =ROUNDUP(J8/((IF(E8=0,C8*INDEX(Preise!$B$5:$B$17,MATCH(F8,Preise!$A$5:$A$17,0)),C8*(E8*INDEX(Preise!$F$5:$F$17,MATCH(F8,Preise!$A$5:$A$17,0))+(1-E8)*INDEX(Preise!$D$5:$D$17,MATCH(F8,Preise!$A$5:$A$17,0))))+D8*INDEX(Preise!$C$5:$C$17,MATCH(F8,Preise!$A$5:$A$17,0)))/1000000)/Arbeitstage,0) -> 34 | L8: =ROUNDUP(J8/((C8*INDEX(Preise!$B$5:$B$17,MATCH(F8,Preise!$A$5:$A$17,0))+D8*INDEX(Preise!$C$5:$C$17,MATCH(F8,Preise!$A$5:$A$17,0)))/1000000)/Arbeitstage,0) -> 11 | M8: dauerhaft mehrere Dokumente im Kontext; Standard-Platz reicht evtl. nicht | N8: =B8*Arbeitstage*(IF(E8=0,C8*INDEX(Preise!$B$5:$B$17,MATCH(F8,Preise!$A$5:$A$17,0)),C8*(E8/2*INDEX(Preise!$F$5:$F$17,MATCH(F8,Preise!$A$5:$A$17,0))+(1-E8/2)*INDEX(Preise!$D$5:$D$17,MATCH(F8,Preise!$A$5:$A$17,0))))+D8*INDEX(Preise!$C$5:$C$17,MATCH(F8,Preise!$A$5:$A$17,0)))/1000000 -> 150.78 | O8: =H8+B8*Arbeitstage*Denk_Tokens_Szenario*INDEX(Preise!$C$5:$C$17,MATCH(F8,Preise!$A$5:$A$17,0))/1000000 -> 81.06
A10: Team mit gemischter Nutzung
A11: Profil | B11: Personen | C11: API ohne Cache (USD) | D11: API mit Cache (USD) | E11: API halber Cache-Anteil (USD) | F11: API mit Cache und Denk-Tokens (USD)
A12: =A5 -> P1 gelegentlich | B12: 3 | C12: =B12*G5 -> 3.78 | D12: =B12*H5 -> 3.78 | E12: =B12*N5 -> 3.78 | F12: =B12*O5 -> 6.93
A13: =A6 -> P2 regelmäßig | B13: 4 | C13: =B13*G6 -> 33.6 | D13: =B13*H6 -> 26.544 | E13: =B13*N6 -> 32.592 | F13: =B13*O6 -> 43.344
A14: =A7 -> P3 intensiv mit Dokumenten | B14: 2 | C14: =B14*G7 -> 105.84 | D14: =B14*H7 -> 52.164 | E14: =B14*N7 -> 88.452 | F14: =B14*O7 -> 77.364
A15: =A8 -> P4 Dauernutzung, lange Dokumente | B15: 1 | C15: =B15*G8 -> 199.5 | D15: =B15*H8 -> 60.06 | E15: =B15*N8 -> 150.78 | F15: =B15*O8 -> 81.06
A16: Personen gesamt | B16: =SUM(B12:B15) -> 10
A17: API-Kosten Chat ohne Cache (USD) | B17: =SUM(C12:C15) -> 342.72
A18: API-Kosten Chat mit Cache (USD) | B18: =SUM(D12:D15) -> 142.548
A19: API-Kosten Chat, halber Cache-Anteil (USD) | B19: =SUM(E12:E15) -> 275.604
A20: API-Kosten Chat mit Cache und Denk-Tokens (USD) | B20: =SUM(F12:F15) -> 208.698
A21: Zusätzlicher API-Bedarf für Automatisierung (USD) | B21: 40 | C21: Annahme, z. B. mehrere Anwendungen aus Kapitel 3
A22: Betreuung einer eigenen Chat-Oberfläche (h/Monat) | B22: 2 | C22: Annahme: Updates, Benutzerverwaltung, Fragen; Einrichtung nicht enthalten
A23: Platz-Abo für alle (USD) | B23: =B16*Abo_Claude_Team -> 200
A24: Im Claude-Team-Abo enthaltenes API-Guthaben (USD) | B24: =MIN(B16*Credit_Claude_Team,Credit_Pool_Max) -> 200
A25: Nur API ohne Zwischenspeicher, eigene Oberfläche (EUR) | B25: =(B17+B21)/USD_je_EUR+B22*Stundensatz -> 422.8
A26: Nur API mit Zwischenspeicher, eigene Oberfläche (EUR) | B26: =(B18+B21)/USD_je_EUR+B22*Stundensatz -> 248.73739
A27: dasselbe ohne Betreuungskosten der Oberfläche (EUR) | B27: =(B18+B21)/USD_je_EUR -> 158.73739
A28: Nur API, halber Cache-Anteil, eigene Oberfläche (EUR) | B28: =(B19+B21)/USD_je_EUR+B22*Stundensatz -> 364.43826
A29: Nur API mit Zwischenspeicher und Denk-Tokens, eigene Oberfläche (EUR) | B29: =(B20+B21)/USD_je_EUR+B22*Stundensatz -> 306.25913
A30: Team-Plätze, Automatisierung aus enthaltenem Guthaben (EUR) | B30: =(B23+MAX(0,B21-B24))/USD_je_EUR -> 173.91304
A31: Team-Plätze mit Premium-Platz für den Dauernutzer (EUR) | B31: =(B23-Abo_Claude_Team+Abo_Claude_Team_Premium+MAX(0,B21-MIN((B16-1)*Credit_Claude_Team+Abo_Claude_Team_Premium,Credit_Pool_Max)))/USD_je_EUR -> 243.47826 | C31: Premium-Platz laut Parameter, enthält Guthaben in Höhe des Platzpreises
A32: Plätze ohne enthaltenes Guthaben, Automatisierung per API (EUR) | B32: =(B23+B21)/USD_je_EUR -> 208.69565
A33: Zahl der Gelegenheitsnutzer im Vergleich | B33: 5 | C33: Annahme
A34: Ersparnis dieser Gelegenheitsnutzer (P1) über die API statt Plätze (EUR) | B34: =B33*(Abo_Claude_Team-H5)/USD_je_EUR -> 81.478261 | C34: Vergleich mit zwei Stunden Betreuung der eigenen Oberfläche
A36: Größeres Team: Verteilung auf die Profile (Annahme)
A37: Personen im Profil P1 | B37: 12
A38: Personen im Profil P2 | B38: 8
A39: Personen im Profil P3 | B39: 4
A40: Personen im Profil P4 | B40: 1
A41: Personen gesamt, größeres Team | B41: =B37+B38+B39+B40 -> 25
A42: API-Kosten Chat mit Cache, größeres Team (USD) | B42: =B37*H5+B38*H6+B39*H7+B40*H8 -> 232.596
A43: Größeres Team: nur API mit Zwischenspeicher, eigene Oberfläche (EUR) | B43: =(B42+B21)/USD_je_EUR+B22*Stundensatz -> 327.04
...

Sheet Arbeitskosten
A1: Arbeitskosten je geleistete Stunde: Beispiel aus Kapitel 5
A2: Annahmen für eine Innendienstkraft. Den Zuschlag für Arbeitgeberanteile kennt die Lohnbuchhaltung genau.
A4: Jahresbruttogehalt | B4: 42000 | C4: Annahme
A5: Zuschlag Arbeitgeberanteile und sonstige Personalkosten | B5: 0.22 | C5: Annahme; Sozialversicherung allein rund 20–21 %, mit Umlagen und Berufsgenossenschaft eher 22–25 %
A6: Wochenstunden | B6: 40 | C6: Annahme
A7: Arbeitstage im Jahr vor Abzügen (52 × 5) | B7: 260
A8: Urlaubstage | B8: 30 | C8: Annahme
A9: Feiertage an Werktagen | B9: 10 | C9: Annahme
A10: Krankheitstage | B10: 12 | C10: Annahme
A12: Geleistete Stunden im Jahr | B12: =(B7-B8-B9-B10)*B6/5 -> 1664
A13: Arbeitskosten je geleistete Stunde | B13: =B4*(1+B5)/B12 -> 30.793269

Sheet Wirtschaftlichkeit
A1: Wirtschaftlichkeitsrechnung (Kapitel 5): Beispielvorgang mit drei Volumina
A2: Alle Beträge netto. Eingaben in Blau, die einflussreichsten gelb. Arbeitskosten aus Blatt Parameter.
A4: Position | B4: geringes Volumen | C4: mittleres Volumen | D4: hohes Volumen | E4: Einheit | F4: Formel / Erläuterung
A5: KI-Kosten je Vorgang
A6: Input-Tokens je Vorgang | B6: 3000 | C6: =$B6 -> 3000 | D6: =$B6 -> 3000 | E6: Tokens | F6: ti: Annahme
A7: Output-Tokens je Vorgang (Antwort) | B7: 500 | C7: =$B7 -> 500 | D7: =$B7 -> 500 | E7: Tokens | F7: to: Annahme
A8: Denk-Tokens je Vorgang | B8: 0 | C8: =$B8 -> 0 | D8: =$B8 -> 0 | E8: Tokens | F8: dt: 0 = Denken abgeschaltet bzw. reduziert; siehe Kapitel 3
A9: Modell | B9: Claude Sonnet 5.5 | C9: =$B9 -> Claude Sonnet 5.5 | D9: =$B9 -> Claude Sonnet 5.5 | F9: M: Auswahl aus Blatt Preise
A10: KI-Kosten je Vorgang | B10: =(B6*INDEX(Preise!$B$5:$B$17,MATCH(B9,Preise!$A$5:$A$17,0))+(B7+B8)*INDEX(Preise!$C$5:$C$17,MATCH(B9,Preise!$A$5:$A$17,0)))/1000000/USD_je_EUR -> 0.0095652174 | C10: =(C6*INDEX(Preise!$B$5:$B$17,MATCH(C9,Preise!$A$5:$A$17,0))+(C7+C8)*INDEX(Preise!$C$5:$C$17,MATCH(C9,Preise!$A$5:$A$17,0)))/1000000/USD_je_EUR -> 0.0095652174 | D10: =(D6*INDEX(Preise!$B$5:$B$17,MATCH(D9,Preise!$A$5:$A$17,0))+(D7+D8)*INDEX(Preise!$C$5:$C$17,MATCH(D9,Preise!$A$5:$A$17,0)))/1000000/USD_je_EUR -> 0.0095652174 | E10: EUR | F10: k
A11: KI-Kosten je Vorgang mit Denk-Tokens laut Parameter (Empfindlichkeit) | B11: =B10+Denk_Tokens_Szenario*INDEX(Preise!$C$5:$C$17,MATCH(B9,Preise!$A$5:$A$17,0))/1000000/USD_je_EUR -> 0.01826087 | C11: =C10+Denk_Tokens_Szenario*INDEX(Preise!$C$5:$C$17,MATCH(C9,Preise!$A$5:$A$17,0))/1000000/USD_je_EUR -> 0.01826087 | D11: =D10+Denk_Tokens_Szenario*INDEX(Preise!$C$5:$C$17,MATCH(D9,Preise!$A$5:$A$17,0))/1000000/USD_je_EUR -> 0.01826087 | E11: EUR | F11: kD: k zuzüglich Denk_Tokens_Szenario zum Output-Preis des Modells
A12: Eingaben je Szenario
A13: Vorgänge je Monat | B13: 150 | C13: 600 | D13: 2500 | E13: Anzahl | F13: V: Annahme
A14: Minuten je Vorgang ohne KI | B14: 6 | C14: 6 | D14: 6 | E14: min | F14: m0: Annahme; vorher selbst messen
A15: Minuten je Vorgang mit KI (Prüfen, Freigeben) | B15: 2 | C15: 2 | D15: 2 | E15: min | F15: m1: Annahme; die menschliche Kontrolle bleibt
A16: Anteil Vorgänge mit Korrektur | B16: 0.08 | C16: 0.08 | D16: 0.08 | E16: % | F16: f: Annahme; im Pilot messen
A17: Minuten je Korrektur | B17: 5 | C17: 5 | D17: 5 | E17: min | F17: mk: Annahme
A18: Feste Software- und Plattformkosten | B18: 25 | C18: 50 | D18: 150 | E18: EUR/Monat | F18: Sw: Annahme
A19: Wartung und Kontrolle (Stichproben, Anpassungen) | B19: 2 | C19: 4 | D19: 8 | E19: h/Monat | F19: Wh: Annahme
A20: Neutest nach Modell- oder Anbieterwechsel | B20: 4 | C20: 8 | D20: 12 | E20: h/Jahr | F20: NT: Annahme
A21: Einrichtung durch Dienstleister | B21: 25 | C21: 50 | D21: 100 | E21: h | F21: Eh: Annahme; bewertet mit externem Stundensatz aus Blatt Parameter
A22: Datenschutz und Recht, einmalig (AVV-Prüfung, Verzeichnis, Information, ggf. Betriebsrat) | B22: 300 | C22: 600 | D22: 1000 | E22: EUR | F22: DS: Annahme
A23: IT-Sicherheit, einmalig (Zugänge, Rechte, Protokollierung) | B23: 200 | C23: 400 | D23: 800 | E23: EUR | F23: IT: Annahme
A24: Schulung | B24: 4 | C24: 12 | D24: 30 | E24: h gesamt | F24: Sh: Annahme
... A26: Zahlungswirksam realisierbarer Anteil der gesparten Zeit | B26: 0 | C26: 0.3 | D26: 0.5 | E26: % | F26: r: Annahme. 0 % = Zeit wird anders genutzt, keine Ausgabe sinkt. Anteil nur ansetzen, wenn Überstunden, Aushilfen oder Fremdleistungen tatsächlich wegfallen.
A27: Ergebnisse
A28: Wartung gesamt inkl. Neutest nach Modellwechseln | B28: =B19+B20/12 -> 2.3333333 | C28: =C19+C20/12 -> 4.6666667 | D28: =D19+D20/12 -> 9 | E28: h/Monat | F28: Wt = Wh + NT / 12
A29: Arbeitszeit ohne KI | B29: =B13*B14/60 -> 15 | C29: =C13*C14/60 -> 60 | D29: =D13*D14/60 -> 250 | E29: h/Monat | F29: T0 = V × m0 / 60
A30: Arbeitszeit mit KI inkl. Korrekturen und Wartung | B30: =(B13*B15+B13*B16*B17)/60+B28 -> 8.3333333 | C30: =(C13*C15+C13*C16*C17)/60+C28 -> 28.666667 | D30: =(D13*D15+D13*D16*D17)/60+D28 -> 109 | E30: h/Monat | F30: T1 = (V × m1 + V × f × mk) / 60 + Wt
A31: Frei werdende Arbeitszeit (Kapazitätsgewinn) | B31: =B29-B30 -> 6.6666667 | C31: =C29-C30 -> 31.333333 | D31: =D29-D30 -> 141 | E31: h/Monat | F31: dT = T0 − T1
A32: Kapazitätsgewinn bewertet | B32: =B31*Stundensatz -> 300 | C32: =C31*Stundensatz -> 1410 | D32: =D31*Stundensatz -> 6345 | E32: EUR/Monat | F32: KG = dT × S
A33: KI-Kosten im Monat | B33: =B13*B10 -> 1.4347826 | C33: =C13*C10 -> 5.7391304 | D33: =D13*D10 -> 23.913043 | E33: EUR/Monat | F33: KM = V × k
A34: Laufende zahlungswirksame Kosten | B34: =B33+B18 -> 26.434783 | C34: =C33+C18 -> 55.73913 | D34: =D33+D18 -> 173.91304 | E34: EUR/Monat | F34: LK = V × k + Software
A35: Kosten je Vorgang ohne KI | B35: =B14/60*Stundensatz -> 4.5 | C35: =C14/60*Stundensatz -> 4.5 | D35: =D14/60*Stundensatz -> 4.5 | E35: EUR | F35: KV0 = m0 / 60 × S
A36: Kosten je Vorgang mit KI | B36: =IF(B13>0,(B30*Stundensatz+B34)/B13,"-") -> 2.6762319 | C36: =IF(C13>0,(C30*Stundensatz+C34)/C13,"-") -> 2.2428986 | D36: =IF(D13>0,(D30*Stundensatz+D34)/D13,"-") -> 2.0315652 | E36: EUR | F36: KV1 = (T1 × S + LK) / V
A37: Nettoeffekt kalkulatorisch | B37: =B32-B34 -> 273.56522 | C37: =C32-C34 -> 1354.2609 | D37: =D32-D34 -> 6171.087 | E37: EUR/Monat | F37: NK = KG − LK
A38: Nettoeffekt zahlungswirksam | B38: =B32*B26-B34 -> -26.434783 | C38: =C32*C26-C34 -> 367.26087 | D38: =D32*D26-D34 -> 2998.587 | E38: EUR/Monat | F38: NZ = r × KG − LK
A39: Einmalkosten zahlungswirksam (extern, Datenschutz, IT-Sicherheit) | B39: =B21*Extern_Stundensatz+B22+B23 -> 3000 | C39: =C21*Extern_Stundensatz+C22+C23 -> 6000 | D39: =D21*Extern_Stundensatz+D22+D23 -> 11800 | E39: EUR | F39: EB = Eh × externer Satz + DS + IT
A40: Interne Einmalstunden bewertet (Schulung, Ist-Aufnahme, Pilot) | B40: =(B24+B25)*Stundensatz -> 540 | C40: =(C24+C25)*Stundensatz -> 1260 | D40: =(D24+D25)*Stundensatz -> 2700 | E40: EUR | F40: EI = (Sh + Ih) × S
A41: Einmalkosten gesamt | B41: =B39+B40 -> 3540 | C41: =C39+C40 -> 7260 | D41: =D39+D40 -> 14500 | E41: EUR | F41: EG = EB + EI
A42: Amortisation kalkulatorisch | B42: =IF(B37>0,B41/B37,"keine") -> 12.940242 | C42: =IF(C37>0,C41/C37,"keine") -> 5.3608578 | D42: =IF(D37>0,D41/D37,"keine") -> 2.3496671 | E42: Monate | F42: AK = EG / NK
...

Sheet Sensitivität
A1: Sensitivität: kalkulatorischer Nettoeffekt je Monat (EUR)
A2: Basis: übrige Annahmen der Spalte mittleres Volumen im Blatt Wirtschaftlichkeit. Zeilen: Vorgänge je Monat. Spalten: Zeitersparnis je Vorgang vor Korrekturen (m0 − m1) in Minuten.
A4: Vorgänge \ Minuten gespart | B4: 0.5 | C4: 1 | D4: 2 | E4: 3 | F4: 4 | G4: 6
A5: 50 | B5: =$A5*(((B$4-Wirtschaftlichkeit!$C$16*Wirtschaftlichkeit!$C$17)/60)*Stundensatz-Wirtschaftlichkeit!$C$10)-Wirtschaftlichkeit!$C$28*Stundensatz-Wirtschaftlichkeit!$C$18 -> -256.72826 | C5: =$A5*(((C$4-Wirtschaftlichkeit!$C$16*Wirtschaftlichkeit!$C$17)/60)*Stundensatz-Wirtschaftlichkeit!$C$10)-Wirtschaftlichkeit!$C$28*Stundensatz-Wirtschaftlichkeit!$C$18 -> -237.97826 | D5: =$A5*(((D$4-Wirtschaftlichkeit!$C$16*Wirtschaftlichkeit!$C$17)/60)*Stundensatz-Wirtschaftlichkeit!$C$10)-Wirtschaftlichkeit!$C$28*Stundensatz-Wirtschaftlichkeit!$C$18 -> -200.47826 | E5: =$A5*(((E$4-Wirtschaftlichkeit!$C$16*Wirtschaftlichkeit!$C$17)/60)*Stundensatz-Wirtschaftlichkeit!$C$10)-Wirtschaftlichkeit!$C$28*Stundensatz-Wirtschaftlichkeit!$C$18 -> -162.97826 | F5: =$A5*(((F$4-Wirtschaftlichkeit!$C$16*Wirtschaftlichkeit!$C$17)/60)*Stundensatz-Wirtschaftlichkeit!$C$10)-Wirtschaftlichkeit!$C$28*Stundensatz-Wirtschaftlichkeit!$C$18 -> -125.47826 | G5: =$A5*(((G$4-Wirtschaftlichkeit!$C$16*Wirtschaftlichkeit!$C$17)/60)*Stundensatz-Wirtschaftlichkeit!$C$10)-Wirtschaftlichkeit!$C$28*Stundensatz-Wirtschaftlichkeit!$C$18 -> -50.478261
A6: 100 | B6: =$A6*(((B$4-Wirtschaftlichkeit!$C$16*Wirtschaftlichkeit!$C$17)/60)*Stundensatz-Wirtschaftlichkeit!$C$10)-Wirtschaftlichkeit!$C$28*Stundensatz-Wirtschaftlichkeit!$C$18 -> -253.45652 | C6: =$A6*(((C$4-Wirtschaftlichkeit!$C$16*Wirtschaftlichkeit!$C$17)/60)*Stundensatz-Wirtschaftlichkeit!$C$10)-Wirtschaftlichkeit!$C$28*Stundensatz-Wirtschaftlichkeit!$C$18 -> -215.95652 | D6: =$A6*(((D$4-Wirtschaftlichkeit!$C$16*Wirtschaftlichkeit!$C$17)/60)*Stundensatz-Wirtschaftlichkeit!$C$10)-Wirtschaftlichkeit!$C$28*Stundensatz-Wirtschaftlichkeit!$C$18 -> -140.95652 | E6: =$A6*(((E$4-Wirtschaftlichkeit!$C$16*Wirtschaftlichkeit!$C$17)/60)*Stundensatz-Wirtschaftlichkeit!$C$10)-Wirtschaftlichkeit!$C$28*Stundensatz-Wirtschaftlichkeit!$C$18 -> -65.956522 | F6: =$A6*(((F$4-Wirtschaftlichkeit!$C$16*Wirtschaftlichkeit!$C$17)/60)*Stundensatz-Wirtschaftlichkeit!$C$10)-Wirtschaftlichkeit!$C$28*Stundensatz-Wirtschaftlichkeit!$C$18 -> 9.0434783 | G6: =$A6*(((G$4-Wirtschaftlichkeit!$C$16*Wirtschaftlichkeit!$C$17)/60)*Stundensatz-Wirtschaftlichkeit!$C$10)-Wirtschaftlichkeit!$C$28*Stundensatz-Wirtschaftlichkeit!$C$18 -> 159.04348
A7: 250 | B7: =$A7*(((B$4-Wirtschaftlichkeit!$C$16*Wirtschaftlichkeit!$C$17)/60)*Stundensatz-Wirtschaftlichkeit!$C$10)-Wirtschaftlichkeit!$C$28*Stundensatz-Wirtschaftlichkeit!$C$18 -> -243.6413 | C7: =$A7*(((C$4-Wirtschaftlichkeit!$C$16*Wirtschaftlichkeit!$C$17)/60)*Stundensatz-Wirtschaftlichkeit!$C$10)-Wirtschaftlichkeit!$C$28*Stundensatz-Wirtschaftlichkeit!$C$18 -> -149.8913 | D7: =$A7*(((D$4-Wirtschaftlichkeit!$C$16*Wirtschaftlichkeit!$C$17)/60)*Stundensatz-Wirtschaftlichkeit!$C$10)-Wirtschaftlichkeit!$C$28*Stundensatz-Wirtschaftlichkeit!$C$18 -> 37.608696 | E7: =$A7*(((E$4-Wirtschaftlichkeit!$C$16*Wirtschaftlichkeit!$C$17)/60)*Stundensatz-Wirtschaftlichkeit!$C$10)-Wirtschaftlichkeit!$C$28*Stundensatz-Wirtschaftlichkeit!$C$18 -> 225.1087 | F7: =$A7*(((F$4-Wirtschaftlichkeit!$C$16*Wirtschaftlichkeit!$C$17)/60)*Stundensatz-Wirtschaftlichkeit!$C$10)-Wirtschaftlichkeit!$C$28*Stundensatz-Wirtschaftlichkeit!$C$18 -> 412.6087 | G7: =$A7*(((G$4-Wirtschaftlichkeit!$C$16*Wirtschaftlichkeit!$C$17)/60)*Stundensatz-Wirtschaftlichkeit!$C$10)-Wirtschaftlichkeit!$C$28*Stundensatz-Wirtschaftlichkeit!$C$18 -> 787.6087
A8: 500 | B8: =$A8*(((B$4-Wirtschaftlichkeit!$C$16*Wirtschaftlichkeit!$C$17)/60)*Stundensatz-Wirtschaftlichkeit!$C$10)-Wirtschaftlichkeit!$C$28*Stundensatz-Wirtschaftlichkeit!$C$18 -> -227.28261 | C8: =$A8*(((C$4-Wirtschaftlichkeit!$C$16*Wirtschaftlichkeit!$C$17)/60)*Stundensatz-Wirtschaftlichkeit!$C$10)-Wirtschaftlichkeit!$C$28*Stundensatz-Wirtschaftlichkeit!$C$18 -> -39.782609 | D8: =$A8*(((D$4-Wirtschaftlichkeit!$C$16*Wirtschaftlichkeit!$C$17)/60)*Stundensatz-Wirtschaftlichkeit!$C$10)-Wirtschaftlichkeit!$C$28*Stundensatz-Wirtschaftlichkeit!$C$18 -> 335.21739 | E8: =$A8*(((E$4-Wirtschaftlichkeit!$C$16*Wirtschaftlichkeit!$C$17)/60)*Stundensatz-Wirtschaftlichkeit!$C$10)-Wirtschaftlichkeit!$C$28*Stundensatz-Wirtschaftlichkeit!$C$18 -> 710.21739 | F8: =$A8*(((F$4-Wirtschaftlichkeit!$C$16*Wirtschaftlichkeit!$C$17)/60)*Stundensatz-Wirtschaftlichkeit!$C$10)-Wirtschaftlichkeit!$C$28*Stundensatz-Wirtschaftlichkeit!$C$18 -> 1085.2174 | G8: =$A8*(((G$4-Wirtschaftlichkeit!$C$16*Wirtschaftlichkeit!$C$17)/60)*Stundensatz-Wirtschaftlichkeit!$C$10)-Wirtschaftlichkeit!$C$28*Stundensatz-Wirtschaftlichkeit!$C$18 -> 1835.2174
A9: 1000 | B9: =$A9*(((B$4-Wirtschaftlichkeit!$C$16*Wirtschaftlichkeit!$C$17)/60)*Stundensatz-Wirtschaftlichkeit!$C$10)-Wirtschaftlichkeit!$C$28*Stundensatz-Wirtschaftlichkeit!$C$18 -> -194.56522 | C9: =$A9*(((C$4-Wirtschaftlichkeit!$C$16*Wirtschaftlichkeit!$C$17)/60)*Stundensatz-Wirtschaftlichkeit!$C$10)-Wirtschaftlichkeit!$C$28*Stundensatz-Wirtschaftlichkeit!$C$18 -> 180.43478 | D9: =$A9*(((D$4-Wirtschaftlichkeit!$C$16*Wirtschaftlichkeit!$C$17)/60)*Stundensatz-Wirtschaftlichkeit!$C$10)-Wirtschaftlichkeit!$C$28*Stundensatz-Wirtschaftlichkeit!$C$18 -> 930.43478 | E9: =$A9*(((E$4-Wirtschaftlichkeit!$C$16*Wirtschaftlichkeit!$C$17)/60)*Stundensatz-Wirtschaftlichkeit!$C$10)-Wirtschaftlichkeit!$C$28*Stundensatz-Wirtschaftlichkeit!$C$18 -> 1680.4348 | F9: =$A9*(((F$4-Wirtschaftlichkeit!$C$16*Wirtschaftlichkeit!$C$17)/60)*Stundensatz-Wirtschaftlichkeit!$C$10)-Wirtschaftlichkeit!$C$28*Stundensatz-Wirtschaftlichkeit!$C$18 -> 2430.4348 | G9: =$A9*(((G$4-Wirtschaftlichkeit!$C$16*Wirtschaftlichkeit!$C$17)/60)*Stundensatz-Wirtschaftlichkeit!$C$10)-Wirtschaftlichkeit!$C$28*Stundensatz-Wirtschaftlichkeit!$C$18 -> 3930.4348
A10: 2500 | B10: =$A10*(((B$4-Wirtschaftlichkeit!$C$16*Wirtschaftlichkeit!$C$17)/60)*Stundensatz-Wirtschaftlichkeit!$C$10)-Wirtschaftlichkeit!$C$28*Stundensatz-Wirtschaftlichkeit!$C$18 -> -96.413043 | C10: =$A10*(((C$4-Wirtschaftlichkeit!$C$16*Wirtschaftlichkeit!$C$17)/60)*Stundensatz-Wirtschaftlichkeit!$C$10)-Wirtschaftlichkeit!$C$28*Stundensatz-Wirtschaftlichkeit!$C$18 -> 841.08696 | D10: =$A10*(((D$4-Wirtschaftlichkeit!$C$16*Wirtschaftlichkeit!$C$17)/60)*Stundensatz-Wirtschaftlichkeit!$C$10)-Wirtschaftlichkeit!$C$28*Stundensatz-Wirtschaftlichkeit!$C$18 -> 2716.087 | E10: =$A10*(((E$4-Wirtschaftlichkeit!$C$16*Wirtschaftlichkeit!$C$17)/60)*Stundensatz-Wirtschaftlichkeit!$C$10)-Wirtschaftlichkeit!$C$28*Stundensatz-Wirtschaftlichkeit!$C$18 -> 4591.087 | F10: =$A10*(((F$4-Wirtschaftlichkeit!$C$16*Wirtschaftlichkeit!$C$17)/60)*Stundensatz-Wirtschaftlichkeit!$C$10)-Wirtschaftlichkeit!$C$28*Stundensatz-Wirtschaftlichkeit!$C$18 -> 6466.087 | G10: =$A10*(((G$4-Wirtschaftlichkeit!$C$16*Wirtschaftlichkeit!$C$17)/60)*Stundensatz-Wirtschaftlichkeit!$C$10)-Wirtschaftlichkeit!$C$28*Stundensatz-Wirtschaftlichkeit!$C$18 -> 10216.087
